Workbook

Sheet Pivot Tables
A1: Country | B1: (All) | G1: Datewise Layoff | H1: (All) | P1: Years (Date) | Q1: (All) | V1: Years (Date) | W1: (All)
A2: Country/Layoff | D2: Industry/Layoff | G2: Company/Layoff | J2: Company/Layoff | M2: Company/Layoff | P2: Company/Layoff | V2: Company/Layoff
A3: Row Labels | B3: Sum of Laid_Off_Count | D3: Row Labels | E3: Sum of Laid_Off_Count | G3: Row Labels | H3: Sum of Laid_Off_Count | J3: Row Labels | K3: Sum of Laid_Off_Count | M3: Row Labels | N3: Sum of Funds_Raised | P3: Row Labels | Q3: Sum of Laid_Off_Count | R3: Sum of Funds_Raised | S3: Average of Percentage | T3: Layoffs Intensity | U3: Risk Score | V3: Row Labels | W3: Sum of Laid_Off_Count
A4: Abuja | B4: 0 | D4: Aerospace | E4: 1188 | G4: 99 | H4: 75 | J4: Argentina | K4: 323 | M4: 99 | N4: 244 | P4: 99 | Q4: 75 | R4: 244 | S4: 0.02 | T4: =IFERROR(ROUND((Q4/R4),2),"NA") -> 0.31 | U4: =Q4*S4 -> 1.5 | V4: Jan | W4: 131139
A5: Accra | B5: 150 | D5: AI | E5: 262 | G5: 888 | H5: 0 | J5: Australia | K5: 3623 | M5: 888 | N5: 0 | P5: 888 | Q5: 0 | R5: 0 | S5: 0 | T5: =IFERROR(ROUND((Q5/R5),2),"NA") -> NA | U5: =Q5*S5 -> 0 | V5: Feb | W5: 60094
A6: Ahmedabad | B6: 500 | D6: Construction | E6: 3863 | G6: Sunday | H6: 90 | J6: Austria | K6: 740 | M6: Sunday | N6: 124 | P6: Sunday | Q6: 90 | R6: 124 | S6: 0.23 | T6: =IFERROR(ROUND((Q6/R6),2),"NA") -> 0.73 | U6: =Q6*S6 -> 20.7 | V6: Mar | W6: 60755
A7: Alamosa | B7: 0 | D7: Consumer | E7: 67675 | G7: Thursday | H7: 0 | J7: Bahrain | K7: 0 | M7: Thursday | N7: 3 | P7: Thursday | Q7: 0 | R7: 3 | S7: 0.7 | T7: =IFERROR(ROUND((Q7/R7),2),"NA") -> 0 | U7: =Q7*S7 -> 0 | V7: Apr | W7: 73601
A8: Albany | B8: 371 | D8: Crypto | E8: 13618 | G8: E Inc. | H8: 0 | J8: Belgium | K8: 50 | M8: E Inc. | N8: 0 | P8: E Inc. | Q8: 0 | R8: 0 | S8: 0 | T8: =IFERROR(ROUND((Q8/R8),2),"NA") -> NA | U8: =Q8*S8 -> 0 | V8: May | W8: 63871
A9: Amsterdam | B9: 18065 | D9: Data | E9: 8855 | G9: F-Secure | H9: 70 | J9: Brazil | K9: 11323 | M9: F-Secure | N9: 0 | P9: F-Secure | Q9: 70 | R9: 0 | S9: 0 | T9: =IFERROR(ROUND((Q9/R9),2),"NA") -> NA | U9: =Q9*S9 -> 0 | V9: Jun | W9: 40821
A10: Ann Arbor | B10: 340 | D10: Education | E10: 18510 | G10: Included Health | H10: 0 | J10: Bulgaria | K10: 120 | M10: Included Health | N10: 272 | P10: Included Health | Q10: 0 | R10: 272 | S10: 0.06 | T10: =IFERROR(ROUND((Q10/R10),2),"NA") -> 0 | U10: =Q10*S10 -> 0 | V10: Jul | W10: 34080
A11: Athens | B11: 0 | D11: Energy | E11: 3067 | G11: &Open | H11: 9 | J11: Canada | K11: 10321 | M11: &Open | N11: 35 | P11: &Open | Q11: 9 | R11: 35 | S11: 0.09 | T11: =IFERROR(ROUND((Q11/R11),2),"NA") -> 0.26 | U11: =Q11*S11 -> 0.81 | V11: Aug | W11: 27069
A12: Atlanta | B12: 2315 | D12: Finance | E12: 43103 | G12: #Paid | H12: 19 | J12: Cayman Islands | K12: 1060 | M12: #Paid | N12: 21 | P12: #Paid | Q12: 19 | R12: 21 | S12: 0.17 | T12: =IFERROR(ROUND((Q12/R12),2),"NA") -> 0.9 | U12: =Q12*S12 -> 3.23 | V12: Sep | W12: 11358
A13: Auckland | B13: 300 | D13: Fitness | E13: 9671 | G13: 100 Thieves | H13: 12 | J13: Chile | K13: 525 | M13: 100 Thieves | N13: 240 | P13: 100 Thieves | Q13: 12 | R13: 240 | S13: 0 | T13: =IFERROR(ROUND((Q13/R13),2),"NA") -> 0.05 | U13: =Q13*S13 -> 0 | V13: Oct | W13: 29219
A14: Austin | B14: 33545 | D14: Food | E14: 45625 | G14: 10X Genomics | H14: 100 | J14: China | K14: 7190 | M14: 10X Genomics | N14: 242 | P14: 10X Genomics | Q14: 100 | R14: 242 | S14: 0.08 | T14: =IFERROR(ROUND((Q14/R14),2),"NA") -> 0.41 | U14: =Q14*S14 -> 8 | V14: Nov | W14: 64274
A15: Baltimore | B15: 170 | D15: Hardware | E15: 37750 | G15: 123Milhas | H15: 0 | J15: Colombia | K15: 130 | M15: 123Milhas | N15: 0 | P15: 123Milhas | Q15: 0 | R15: 0 | S15: 0 | T15: =IFERROR(ROUND((Q15/R15),2),"NA") -> NA | U15: =Q15*S15 -> 0 | V15: Dec | W15: 19905
A16: Bangkok | B16: 55 | D16: Healthcare | E16: 36907 | G16: 1K Kirana | H16: 600 | J16: Czech Republic | K16: 316 | M16: 1K Kirana | N16: 0 | P16: 1K Kirana | Q16: 600 | R16: 0 | S16: 0.4 | T16: =IFERROR(ROUND((Q16/R16),2),"NA") -> NA | U16: =Q16*S16 -> 240
A17: Barcelona | B17: 435 | D17: HR | E17: 8197 | G17: 1stdibs | H17: 70 | J17: Denmark | K17: 319 | M17: 1stdibs | N17: 253 | P17: 1stdibs | Q17: 70 | R17: 253 | S17: 0.17 | T17: =IFERROR(ROUND((Q17/R17),2),"NA") -> 0.28 | U17: =Q17*S17 -> 11.9
A18: Baton Rouge | B18: 200 | D18: Infrastructure | E18: 14974 | G18: 23andMe | H18: 146 | J18: Egypt | K18: 0 | M18: 23andMe | N18: 2200 | P18: 23andMe | Q18: 146 | R18: 2200 | S18: 0.1 | T18: =IFERROR(ROUND((Q18/R18),2),"NA") -> 0.07 | U18: =Q18*S18 -> 14.6
A19: Beau Vallon | B19: 0 | D19: Legal | E19: 966 | G19: 2TM | H19: 190 | J19: Estonia | K19: 582 | M19: 2TM | N19: 500 | P19: 2TM | Q19: 190 | R19: 500 | S19: 0.135 | T19: =IFERROR(ROUND((Q19/R19),2),"NA") -> 0.38 | U19: =Q19*S19 -> 25.65
A20: Beijing | B20: 775 | D20: Logistics | E20: 5356 | G20: 2U | H20: 0 | J20: Finland | K20: 320 | M20: 2U | N20: 1278 | P20: 2U | Q20: 0 | R20: 1278 | S20: 0.2 | T20: =IFERROR(ROUND((Q20/R20),2),"NA") -> 0 | U20: =Q20*S20 -> 0
A21: Belo Horizonte | B21: 576 | D21: Manufacturing | E21: 5642 | G21: 54gene | H21: 95 | J21: France | K21: 1825 | M21: 54gene | N21: 44 | P21: 54gene | Q21: 95 | R21: 44 | S21: 0.3 | T21: =IFERROR(ROUND((Q21/R21),2),"NA") -> 2.16 | U21: =Q21*S21 -> 28.5
A22: Bend | B22: 50 | D22: Marketing | E22: 12413 | G22: 5B Solar | H22: 0 | J22: Germany | K22: 26353 | M22: 5B Solar | N22: 12 | P22: 5B Solar | Q22: 0 | R22: 12 | S22: 0.25 | T22: =IFERROR(ROUND((Q22/R22),2),"NA") -> 0 | U22: =Q22*S22 -> 0
A23: Bengaluru | B23: 30207 | D23: Media | E23: 9255 | G23: 6sense | H23: 150 | J23: Ghana | K23: 150 | M23: 6sense | N23: 426 | P23: 6sense | Q23: 150 | R23: 426 | S23: 0.1 | T23: =IFERROR(ROUND((Q23/R23),2),"NA") -> 0.35 | U23: =Q23*S23 -> 15
A24: Berlin | B24: 13786 | D24: Other | E24: 59261 | G24: 7Shifts | H24: 98 | J24: Greece | K24: 0 | M24: 7Shifts | N24: 262 | P24: 7Shifts | Q24: 98 | R24: 262 | S24: 0.13 | T24: =IFERROR(ROUND((Q24/R24),2),"NA") -> 0.37 | U24: =Q24*S24 -> 12.74
A25: Birmingham | B25: 110 | D25: Product | E25: 2097 | G25: 80 Acres Farms | H25: 0 | J25: Hong Kong | K25: 730 | M25: 80 Acres Farms | N25: 275 | P25: 80 Acres Farms | Q25: 0 | R25: 275 | S25: 0.1 | T25: =IFERROR(ROUND((Q25/R25),2),"NA") -> 0 | U25: =Q25*S25 -> 0
A26: Bismarck | B26: 0 | D26: Real Estate | E26: 19108 | G26: 8x8 | H26: 355 | J26: Hungary | K26: 0 | M26: 8x8 | N26: 506 | P26: 8x8 | Q26: 355 | R26: 506 | S26: 0.08 | T26: =IFERROR(ROUND((Q26/R26),2),"NA") -> 0.7 | U26: =Q26*S26 -> 28.4
A27: Blumenau | B27: 201 | D27: Recruiting | E27: 5101 | G27: 98point6 | H27: 0 | J27: India | K27: 51234 | M27: 98point6 | N27: 546 | P27: 98point6 | Q27: 0 | R27: 546 | S27: 0.1 | T27: =IFERROR(ROUND((Q27/R27),2),"NA") -> 0 | U27: =Q27*S27 -> 0
... A34: Bristol | B34: 38 | D34: Unknown | E34: 35 | G34: Acorns | H34: 50 | J34: Lithuania | K34: 60 | M34: Acorns | N34: 207 | P34: Acorns | Q34: 50 | R34: 207 | S34: 0 | T34: =IFERROR(ROUND((Q34/R34),2),"NA") -> 0.24 | U34: =Q34*S34 -> 0
A35: Brno | B35: 216 | D35: (blank) | G35: Acronis | H35: 0 | J35: Luxembourg | K35: 45 | M35: Acronis | N35: 658 | P35: Acronis | Q35: 0 | R35: 658 | S35: 0 | T35: =IFERROR(ROUND((Q35/R35),2),"NA") -> 0 | U35: =Q35*S35 -> 0
A36: Brussels | B36: 0 | G36: Actifio | H36: 54 | J36: Malaysia | K36: 100 | M36: Actifio | N36: 352 | P36: Actifio | Q36: 54 | R36: 352 | S36: 0 | T36: =IFERROR(ROUND((Q36/R36),2),"NA") -> 0.15 | U36: =Q36*S36 -> 0
A37: Bucharest | B37: 80 | G37: ActiveCampaign | H37: 0 | J37: Mexico | K37: 270 | M37: ActiveCampaign | N37: 360 | P37: ActiveCampaign | Q37: 0 | R37: 360 | S37: 0.15 | T37: =IFERROR(ROUND((Q37/R37),2),"NA") -> 0 | U37: =Q37*S37 -> 0
A38: Budapest | B38: 0 | G38: Actyv.ai | H38: 0 | J38: Myanmar | K38: 200 | M38: Actyv.ai | N38: 12 | P38: Actyv.ai | Q38: 0 | R38: 12 | S38: 0.6 | T38: =IFERROR(ROUND((Q38/R38),2),"NA") -> 0 | U38: =Q38*S38 -> 0
A39: Buenos Aires | B39: 323 | G39: Acxiom | H39: 0 | J39: Netherlands | K39: 18445 | M39: Acxiom | N39: 0 | P39: Acxiom | Q39: 0 | R39: 0 | S39: 0 | T39: =IFERROR(ROUND((Q39/R39),2),"NA") -> NA | U39: =Q39*S39 -> 0
A40: Burlington | B40: 47 | G40: Ada | H40: 78 | J40: New Zealand | K40: 1100 | M40: Ada | N40: 380 | P40: Ada | Q40: 78 | R40: 380 | S40: 0.16 | T40: =IFERROR(ROUND((Q40/R40),2),"NA") -> 0.21 | U40: =Q40*S40 -> 12.48
A41: Cairo | B41: 0 | G41: Ada Health | H41: 50 | J41: Nigeria | K41: 2045 | M41: Ada Health | N41: 189 | P41: Ada Health | Q41: 50 | R41: 189 | S41: 0 | T41: =IFERROR(ROUND((Q41/R41),2),"NA") -> 0.26 | U41: =Q41*S41 -> 0
A42: Calgary | B42: 308 | G42: Ada Support | H42: 36 | J42: Norway | K42: 605 | M42: Ada Support | N42: 60 | P42: Ada Support | Q42: 36 | R42: 60 | S42: 0.23 | T42: =IFERROR(ROUND((Q42/R42),2),"NA") -> 0.6 | U42: =Q42*S42 -> 8.28
A43: Cape Town | B43: 0 | G43: Adaptive Biotechnologies | H43: 100 | J43: Pakistan | K43: 0 | M43: Adaptive Biotechnologies | N43: 406 | P43: Adaptive Biotechnologies | Q43: 100 | R43: 406 | S43: 0.12 | T43: =IFERROR(ROUND((Q43/R43),2),"NA") -> 0.25 | U43: =Q43*S43 -> 12
A44: Cayman Islands | B44: 1060 | G44: Adara | H44: 0 | J44: Peru | K44: 0 | M44: Adara | N44: 67 | P44: Adara | Q44: 0 | R44: 67 | S44: 0 | T44: =IFERROR(ROUND((Q44/R44),2),"NA") -> 0 | U44: =Q44*S44 -> 0
A45: Charleston | B45: 500 | G45: Adda247 | H45: 300 | J45: Philippines | K45: 0 | M45: Adda247 | N45: 61 | P45: Adda247 | Q45: 300 | R45: 61 | S45: 0 | T45: =IFERROR(ROUND((Q45/R45),2),"NA") -> 4.92 | U45: =Q45*S45 -> 0
A46: Charlotte | B46: 394 | G46: Addepar | H46: 20 | J46: Poland | K46: 453 | M46: Addepar | N46: 491 | P46: Addepar | Q46: 20 | R46: 491 | S46: 0.03 | T46: =IFERROR(ROUND((Q46/R46),2),"NA") -> 0.04 | U46: =Q46*S46 -> 0.6
...

Sheet Reports
A1: Which industries are collapsing fastest? | B1: =INDEX('Pivot Tables'!D3:D33, MATCH(GETPIVOTDATA("Laid_Off_Count",'Pivot Tables'!$D$3,"Industry","Finance"), 'Pivot Tables'!E3:E34, 0)) -> Finance | C1: =VLOOKUP(B1,'Pivot Tables'!D:E,2,) -> 43103 | D1: financial industry laidoff 451 empolyees | E1: LAYOFF REPORT 2020-2024
A2: Which countries are losing jobs fastest? | B2: =INDEX('Pivot Tables'!J3:J65,MATCH(C2,'Pivot Tables'!K3:K65,0)) -> United States | C2: =MAX('Pivot Tables'!K3:K65) -> 414013 | D2: United states loosing jobs faster
A3: Are well-funded startups still laying off people?
A4: Rank | B4: Companies | C4: Max Funds raised | D4: Layoff | E4: Layoff Efficiency | F4: Layoff Efficiency measures the number of employees laid off relative to the amount of funding raised by the company. It helps identify whether highly funded companies are still reducing workforce despite strong capital support. | I4: Netflix raised very high funding but had relatively smaller layoffs. Uber shows layoffs despite significant funding. Meta has extremely large layoffs compared with other companies.
A5: 1 | B5: =INDEX('Pivot Tables'!M3:M2594,MATCH(C5,'Pivot Tables'!N3:N2594,0)) -> Netflix | C5: =LARGE('Pivot Tables'!$N$4:$N$2594,1) -> 487600 | D5: =_xlfn.XLOOKUP(B5,'Pivot Tables'!P:P,'Pivot Tables'!Q:Q) -> 505 | E5: =_xlfn.XLOOKUP(B5,'Pivot Tables'!P:P,'Pivot Tables'!T:T) -> 0
A6: 2 | B6: =INDEX('Pivot Tables'!M4:M2595,MATCH(C6,'Pivot Tables'!N4:N2595,0)) -> Uber | C6: =LARGE('Pivot Tables'!$N$4:$N$2594,2) -> 148700 | D6: =_xlfn.XLOOKUP(B6,'Pivot Tables'!P:P,'Pivot Tables'!Q:Q) -> 7785 | E6: =_xlfn.XLOOKUP(B6,'Pivot Tables'!P:P,'Pivot Tables'!T:T) -> 0.05
A7: 3 | B7: =INDEX('Pivot Tables'!M5:M2596,MATCH(C7,'Pivot Tables'!N5:N2596,0)) -> Meta | C7: =LARGE('Pivot Tables'!$N$4:$N$2594,3) -> 104000 | D7: =_xlfn.XLOOKUP(B7,'Pivot Tables'!P:P,'Pivot Tables'!Q:Q) -> 21000 | E7: =_xlfn.XLOOKUP(B7,'Pivot Tables'!P:P,'Pivot Tables'!T:T) -> 0.2
A8: 4 | B8: =INDEX('Pivot Tables'!M6:M2597,MATCH(C8,'Pivot Tables'!N6:N2597,0)) -> Rivian | C8: =LARGE('Pivot Tables'!$N$4:$N$2594,4) -> 78000 | D8: =_xlfn.XLOOKUP(B8,'Pivot Tables'!P:P,'Pivot Tables'!Q:Q) -> 1170 | E8: =_xlfn.XLOOKUP(B8,'Pivot Tables'!P:P,'Pivot Tables'!T:T) -> 0.02
A9: 5 | B9: =INDEX('Pivot Tables'!M7:M2598,MATCH(C9,'Pivot Tables'!N7:N2598,0)) -> Tesla | C9: =LARGE('Pivot Tables'!$N$4:$N$2594,5) -> 60600 | D9: =_xlfn.XLOOKUP(B9,'Pivot Tables'!P:P,'Pivot Tables'!Q:Q) -> 14500 | E9: =_xlfn.XLOOKUP(B9,'Pivot Tables'!P:P,'Pivot Tables'!T:T) -> 0.24
A10: Are layoffs increasing month by month?
L11: According to the pattern layoff in January month was relatively high as comparison to another months.This data comprises of data from 2020-2024.We can change it through filters in pivot table linked to this chart.
A26: What re max risk score companies?
A27: Rank | B27: Companies | C27: Max Funds raised | D27: Layoff | E27: Risk Score | F27: Risk score for companies like meta ,BlockFi and others is more which indicates instability in the job for particular companies is more
A28: 1 | B28: =_xlfn.XLOOKUP(C28,'Pivot Tables'!R:R,'Pivot Tables'!P:P) -> Meta | C28: =_xlfn.XLOOKUP(D28,'Pivot Tables'!Q:Q,'Pivot Tables'!R:R) -> 104000 | D28: =_xlfn.XLOOKUP(E28,'Pivot Tables'!U:U,'Pivot Tables'!Q:Q) -> 21000 | E28: =LARGE('Pivot Tables'!U4:U2595,1) -> 2730
A29: 2 | B29: =_xlfn.XLOOKUP(C29,'Pivot Tables'!R:R,'Pivot Tables'!P:P) -> BlockFi | C29: =_xlfn.XLOOKUP(D29,'Pivot Tables'!Q:Q,'Pivot Tables'!R:R) -> 2000 | D29: =_xlfn.XLOOKUP(E29,'Pivot Tables'!U:U,'Pivot Tables'!Q:Q) -> 8100 | E29: =LARGE('Pivot Tables'!U4:U2595,2) -> 2268
A30: 3 | B30: =_xlfn.XLOOKUP(C30,'Pivot Tables'!R:R,'Pivot Tables'!P:P) -> Uber | C30: =_xlfn.XLOOKUP(D30,'Pivot Tables'!Q:Q,'Pivot Tables'!R:R) -> 148700 | D30: =_xlfn.XLOOKUP(E30,'Pivot Tables'!U:U,'Pivot Tables'!Q:Q) -> 7785 | E30: =LARGE('Pivot Tables'!U4:U2595,3) -> 1459.6875
A31: 4 | B31: =_xlfn.XLOOKUP(C31,'Pivot Tables'!R:R,'Pivot Tables'!P:P) -> Tesla | C31: =_xlfn.XLOOKUP(D31,'Pivot Tables'!Q:Q,'Pivot Tables'!R:R) -> 60600 | D31: =_xlfn.XLOOKUP(E31,'Pivot Tables'!U:U,'Pivot Tables'!Q:Q) -> 14500 | E31: =LARGE('Pivot Tables'!U4:U2595,4) -> 1450
A32: 5 | B32: =_xlfn.XLOOKUP(C32,'Pivot Tables'!R:R,'Pivot Tables'!P:P) -> Twitter | C32: =_xlfn.XLOOKUP(D32,'Pivot Tables'!Q:Q,'Pivot Tables'!R:R) -> 44400 | D32: =_xlfn.XLOOKUP(E32,'Pivot Tables'!U:U,'Pivot Tables'!Q:Q) -> 3940 | E32: =LARGE('Pivot Tables'!U4:U2595,5) -> 1182
A33: 6 | B33: =_xlfn.XLOOKUP(C33,'Pivot Tables'!R:R,'Pivot Tables'!P:P) -> 888 | C33: =_xlfn.XLOOKUP(D33,'Pivot Tables'!Q:Q,'Pivot Tables'!R:R) -> 0 | D33: =_xlfn.XLOOKUP(E33,'Pivot Tables'!U:U,'Pivot Tables'!Q:Q) -> 4601 | E33: =LARGE('Pivot Tables'!U4:U2595,6) -> 1150.25
A34: 7 | B34: =_xlfn.XLOOKUP(C34,'Pivot Tables'!R:R,'Pivot Tables'!P:P) -> Katerra | C34: =_xlfn.XLOOKUP(D34,'Pivot Tables'!Q:Q,'Pivot Tables'!R:R) -> 4100 | D34: =_xlfn.XLOOKUP(E34,'Pivot Tables'!U:U,'Pivot Tables'!Q:Q) -> 3074 | E34: =LARGE('Pivot Tables'!U4:U2595,7) -> 1127.1333
A35: 8 | B35: =_xlfn.XLOOKUP(C35,'Pivot Tables'!R:R,'Pivot Tables'!P:P) -> Groupon | C35: =_xlfn.XLOOKUP(D35,'Pivot Tables'!Q:Q,'Pivot Tables'!R:R) -> 4200 | D35: =_xlfn.XLOOKUP(E35,'Pivot Tables'!U:U,'Pivot Tables'!Q:Q) -> 3800 | E35: =LARGE('Pivot Tables'!U4:U2595,8) -> 1121
A36: 9 | B36: =_xlfn.XLOOKUP(C36,'Pivot Tables'!R:R,'Pivot Tables'!P:P) -> 888 | C36: =_xlfn.XLOOKUP(D36,'Pivot Tables'!Q:Q,'Pivot Tables'!R:R) -> 0 | D36: =_xlfn.XLOOKUP(E36,'Pivot Tables'!U:U,'Pivot Tables'!Q:Q) -> 1000 | E36: =LARGE('Pivot Tables'!U4:U2595,9) -> 1000
A37: 10 | B37: =_xlfn.XLOOKUP(C37,'Pivot Tables'!R:R,'Pivot Tables'!P:P) -> Bitwise | C37: =_xlfn.XLOOKUP(D37,'Pivot Tables'!Q:Q,'Pivot Tables'!R:R) -> 84 | D37: =_xlfn.XLOOKUP(E37,'Pivot Tables'!U:U,'Pivot Tables'!Q:Q) -> 900 | E37: =LARGE('Pivot Tables'!U4:U2595,10) -> 900

Sheet layoffs_data 2
A1: Company | B1: Location_HQ | C1: Industry | D1: Laid_Off_Count | E1: Date | F1: Funds_Raised | G1: Stage | H1: Country | I1: Percentage | J1: Monthly Date
A2: Oda | B2: Oslo | C2: Food | D2: 150 | E2: 45448 | F2: 691 | G2: Unknown | H2: Norway | I2: NA | J2: =TEXT(E2,"YYYY-MM") -> 2024-06
A3: Pagaya | B3: Tel Aviv | C3: Finance | D3: 100 | E3: 45448 | F3: 2000 | G3: Post-IPO | H3: Israel | I3: 0.2 | J3: =TEXT(E3,"YYYY-MM") -> 2024-06
A4: Aleph Farms | B4: Tel Aviv | C4: Food | D4: 30 | E4: 45448 | F4: 119 | G4: Unknown | H4: Israel | I4: 0.3 | J4: =TEXT(E4,"YYYY-MM") -> 2024-06
A5: MoonPay | B5: Dover | C5: Crypto | D5: 30 | E5: 45448 | F5: 651 | G5: Unknown | H5: United States | I5: 0.1 | J5: =TEXT(E5,"YYYY-MM") -> 2024-06
A6: Yext | B6: New York City | C6: Marketing | D6: NA | E6: 45448 | F6: 117 | G6: Post-IPO | H6: United States | I6: 0.12 | J6: =TEXT(E6,"YYYY-MM") -> 2024-06
A7: Microsoft | B7: Seattle | C7: Other | D7: 1000 | E7: 45446 | F7: 1 | G7: Post-IPO | H7: United States | I7: NA | J7: =TEXT(E7,"YYYY-MM") -> 2024-06
A8: OrCam | B8: Jerusalem | C8: Healthcare | D8: 100 | E8: 45446 | F8: 86 | G8: Unknown | H8: Israel | I8: 0.5 | J8: =TEXT(E8,"YYYY-MM") -> 2024-06
A9: Google | B9: SF Bay Area | C9: Consumer | D9: 100 | E9: 45443 | F9: 26 | G9: Post-IPO | H9: United States | I9: NA | J9: =TEXT(E9,"YYYY-MM") -> 2024-05
A10: Tropic | B10: New York City | C10: Finance | D10: 40 | E10: 45443 | F10: 67 | G10: Series B | H10: United States | I10: NA | J10: =TEXT(E10,"YYYY-MM") -> 2024-05
A11: Gro Intelligence | B11: New York City | C11: Food | D11: NA | E11: 45443 | F11: 118 | G11: Series B | H11: United States | I11: 0.1 | J11: =TEXT(E11,"YYYY-MM") -> 2024-05
A12: Jasper Health | B12: Boise | C12: Healthcare | D12: NA | E12: 45443 | F12: 32 | G12: Series A | H12: United States | I12: NA | J12: =TEXT(E12,"YYYY-MM") -> 2024-05
A13: FlightStats | B13: Portland | C13: Travel | D13: 73 | E13: 45442 | F13: 3 | G13: Acquired | H13: United States | I13: NA | J13: =TEXT(E13,"YYYY-MM") -> 2024-05
A14: ICANN | B14: Los Angeles | C14: Infrastructure | D14: 33 | E14: 45442 | F14: NA | G14: Unknown | H14: United States | I14: 0.07 | J14: =TEXT(E14,"YYYY-MM") -> 2024-05
A15: Walnut | B15: New York City | C15: Sales | D15: 15 | E15: 45441 | F15: 56 | G15: Series B | H15: United States | I15: 0.2 | J15: =TEXT(E15,"YYYY-MM") -> 2024-05
A16: Fisker | B16: Los Angeles | C16: Transportation | D16: NA | E16: 45441 | F16: 1700 | G16: Post-IPO | H16: United States | I16: NA | J16: =TEXT(E16,"YYYY-MM") -> 2024-05
A17: Funding Circle | B17: London | C17: Finance | D17: NA | E17: 45441 | F17: 746 | G17: Post-IPO | H17: United Kingdom | I17: NA | J17: =TEXT(E17,"YYYY-MM") -> 2024-05
A18: Lucid Motors | B18: SF Bay Area | C18: Transportation | D18: 400 | E18: 45436 | F18: 8300 | G18: Post-IPO | H18: United States | I18: 0.06 | J18: =TEXT(E18,"YYYY-MM") -> 2024-05
A19: Foursquare | B19: New York City | C19: Marketing | D19: 105 | E19: 45435 | F19: 390 | G19: Series G | H19: United States | I19: 0.25 | J19: =TEXT(E19,"YYYY-MM") -> 2024-05
A20: Guild | B20: Denver | C20: Education | D20: 300 | E20: 45434 | F20: 643 | G20: Series F | H20: United States | I20: 0.25 | J20: =TEXT(E20,"YYYY-MM") -> 2024-05
A21: Cue Health | B21: San Diego | C21: Healthcare | D21: 180 | E21: 45434 | F21: 899 | G21: Post-IPO | H21: United States | I21: 1 | J21: =TEXT(E21,"YYYY-MM") -> 2024-05
A22: Silo | B22: SF Bay Area | C22: Food | D22: NA | E22: 45434 | F22: 272 | G22: Series C | H22: United States | I22: 0.3 | J22: =TEXT(E22,"YYYY-MM") -> 2024-05
A23: Joonko | B23: New York City | C23: HR | D23: NA | E23: 45431 | F23: 38 | G23: Series B | H23: United States | I23: 1 | J23: =TEXT(E23,"YYYY-MM") -> 2024-05
A24: Toshiba | B24: Tokyo | C24: Manufacturing | D24: 4000 | E24: 45428 | F24: NA | G24: Unknown | H24: Japan | I24: NA | J24: =TEXT(E24,"YYYY-MM") -> 2024-05
A25: Wefox | B25: Berlin | C25: Finance | D25: 60 | E25: 45428 | F25: 1300 | G25: Series D | H25: Germany | I25: NA | J25: =TEXT(E25,"YYYY-MM") -> 2024-05
A26: Replit | B26: SF Bay Area | C26: Product | D26: 30 | E26: 45428 | F26: 222 | G26: Unknown | H26: United States | I26: 0.2 | J26: =TEXT(E26,"YYYY-MM") -> 2024-05
A27: Gopuff | B27: Philadelphia | C27: Food | D27: NA | E27: 45428 | F27: 3400 | G27: Series H | H27: United States | I27: 0.06 | J27: =TEXT(E27,"YYYY-MM") -> 2024-05
A28: Karhoo | B28: London | C28: Transportation | D28: NA | E28: 45428 | F28: 39 | G28: Acquired | H28: United Kingdom | I28: 1 | J28: =TEXT(E28,"YYYY-MM") -> 2024-05
A29: SeekOut | B29: Seattle | C29: Recruiting | D29: NA | E29: 45428 | F29: NA | G29: Series C | H29: United States | I29: 0.3 | J29: =TEXT(E29,"YYYY-MM") -> 2024-05
A30: Atmosphere | B30: Austin | C30: Other | D30: 100 | E30: 45427 | F30: 214 | G30: Series D | H30: United States | I30: NA | J30: =TEXT(E30,"YYYY-MM") -> 2024-05
A31: Singularity 6 | B31: Los Angeles | C31: Other | D31: 36 | E31: 45427 | F31: 49 | G31: Series B | H31: United States | I31: NA | J31: =TEXT(E31,"YYYY-MM") -> 2024-05
A32: Mainvest | B32: Boston | C32: Finance | D32: NA | E32: 45426 | F32: 3 | G32: Unknown | H32: United States | I32: 1 | J32: =TEXT(E32,"YYYY-MM") -> 2024-05
A33: Indeed | B33: Austin | C33: HR | D33: 1000 | E33: 45425 | F33: 5 | G33: Acquired | H33: United States | I33: 0.08 | J33: =TEXT(E33,"YYYY-MM") -> 2024-05
A34: Motional | B34: Pittsburgh | C34: Transportation | D34: 550 | E34: 45422 | F34: NA | G34: Unknown | H34: United States | I34: 0.4 | J34: =TEXT(E34,"YYYY-MM") -> 2024-05
A35: Rivian | B35: Los Angeles | C35: Transportation | D35: 120 | E35: 45422 | F35: 10700 | G35: Post-IPO | H35: United States | I35: NA | J35: =TEXT(E35,"YYYY-MM") -> 2024-05
A36: Google | B36: SF Bay Area | C36: Consumer | D36: 57 | E36: 45422 | F36: 26 | G36: Post-IPO | H36: United States | I36: NA | J36: =TEXT(E36,"YYYY-MM") -> 2024-05
A37: Vacasa | B37: Portland | C37: Travel | D37: 800 | E37: 45421 | F37: 834 | G37: Post-IPO | H37: United States | I37: 0.13 | J37: =TEXT(E37,"YYYY-MM") -> 2024-05
A38: Sight Diagnostics | B38: Tel Aviv | C38: Healthcare | D38: 40 | E38: 45421 | F38: 124 | G38: Series D | H38: Israel | I38: 0.3 | J38: =TEXT(E38,"YYYY-MM") -> 2024-05
A39: PrepLadder | B39: New Delhi | C39: Education | D39: 145 | E39: 45420 | F39: NA | G39: Acquired | H39: India | I39: 0.25 | J39: =TEXT(E39,"YYYY-MM") -> 2024-05
A40: Simpl | B40: Bengaluru | C40: Finance | D40: 100 | E40: 45420 | F40: 72 | G40: Series B | H40: India | I40: 0.15 | J40: =TEXT(E40,"YYYY-MM") -> 2024-05
...
